[2022-01-31 02:37:26,920] {taskinstance.py:1035} INFO - Dependencies all met for <TaskInstance: extract_load_vehpo.load_vehiclePositions scheduled__2022-01-31T02:34:21.659161+00:00 [queued]>
[2022-01-31 02:37:26,942] {taskinstance.py:1035} INFO - Dependencies all met for <TaskInstance: extract_load_vehpo.load_vehiclePositions scheduled__2022-01-31T02:34:21.659161+00:00 [queued]>
[2022-01-31 02:37:26,955] {taskinstance.py:1241} INFO - 
--------------------------------------------------------------------------------
[2022-01-31 02:37:26,957] {taskinstance.py:1242} INFO - Starting attempt 1 of 1
[2022-01-31 02:37:26,959] {taskinstance.py:1243} INFO - 
--------------------------------------------------------------------------------
[2022-01-31 02:37:27,010] {taskinstance.py:1262} INFO - Executing <Task(PythonOperator): load_vehiclePositions> on 2022-01-31 02:34:21.659161+00:00
[2022-01-31 02:37:27,046] {standard_task_runner.py:52} INFO - Started process 1278 to run task
[2022-01-31 02:37:27,071] {standard_task_runner.py:76} INFO - Running: ['***', 'tasks', 'run', 'extract_load_vehpo', 'load_vehiclePositions', 'scheduled__2022-01-31T02:34:21.659161+00:00', '--job-id', '33', '--raw', '--subdir', 'DAGS_FOLDER/ELT_VehiclePositions.py', '--cfg-path', '/tmp/tmpa36en01_', '--error-file', '/tmp/tmpqzvvg5ob']
[2022-01-31 02:37:27,093] {standard_task_runner.py:77} INFO - Job 33: Subtask load_vehiclePositions
[2022-01-31 02:37:27,321] {logging_mixin.py:109} INFO - Running <TaskInstance: extract_load_vehpo.load_vehiclePositions scheduled__2022-01-31T02:34:21.659161+00:00 [running]> on host 932e3c301250
[2022-01-31 02:37:27,798] {taskinstance.py:1414} INFO - Exporting the following env vars:
AIRFLOW_CTX_DAG_OWNER=juan
AIRFLOW_CTX_DAG_ID=extract_load_vehpo
AIRFLOW_CTX_TASK_ID=load_vehiclePositions
AIRFLOW_CTX_EXECUTION_DATE=2022-01-31T02:34:21.659161+00:00
AIRFLOW_CTX_DAG_RUN_ID=scheduled__2022-01-31T02:34:21.659161+00:00
[2022-01-31 02:37:27,840] {taskinstance.py:1686} ERROR - Task failed with exception
Traceback (most recent call last):
  File "/home/airflow/.local/lib/python3.6/site-packages/airflow/models/taskinstance.py", line 1324, in _run_raw_task
    self._execute_task_with_callbacks(context)
  File "/home/airflow/.local/lib/python3.6/site-packages/airflow/models/taskinstance.py", line 1443, in _execute_task_with_callbacks
    result = self._execute_task(context, self.task)
  File "/home/airflow/.local/lib/python3.6/site-packages/airflow/models/taskinstance.py", line 1499, in _execute_task
    result = execute_callable(context=context)
  File "/home/airflow/.local/lib/python3.6/site-packages/airflow/operators/python.py", line 151, in execute
    return_value = self.execute_callable()
  File "/home/airflow/.local/lib/python3.6/site-packages/airflow/operators/python.py", line 162, in execute_callable
    return self.python_callable(*self.op_args, **self.op_kwargs)
  File "/opt/airflow/dags/ELT_VehiclePositions.py", line 16, in _load_gtfs
    load_gtfs(path)
  File "/opt/airflow/dags/gtfs_elt/functions.py", line 71, in load_gtfs
    with open(path, 'rb') as f:
FileNotFoundError: [Errno 2] No such file or directory: 'vehiclePositions/2022-01-30/vehiclePositions_1643596644'
[2022-01-31 02:37:27,875] {taskinstance.py:1280} INFO - Marking task as FAILED. dag_id=extract_load_vehpo, task_id=load_vehiclePositions, execution_date=20220131T023421, start_date=20220131T023726, end_date=20220131T023727
[2022-01-31 02:37:27,904] {standard_task_runner.py:91} ERROR - Failed to execute job 33 for task load_vehiclePositions
Traceback (most recent call last):
  File "/home/airflow/.local/lib/python3.6/site-packages/airflow/task/task_runner/standard_task_runner.py", line 85, in _start_by_fork
    args.func(args, dag=self.dag)
  File "/home/airflow/.local/lib/python3.6/site-packages/airflow/cli/cli_parser.py", line 48, in command
    return func(*args, **kwargs)
  File "/home/airflow/.local/lib/python3.6/site-packages/airflow/utils/cli.py", line 92, in wrapper
    return f(*args, **kwargs)
  File "/home/airflow/.local/lib/python3.6/site-packages/airflow/cli/commands/task_command.py", line 292, in task_run
    _run_task_by_selected_method(args, dag, ti)
  File "/home/airflow/.local/lib/python3.6/site-packages/airflow/cli/commands/task_command.py", line 107, in _run_task_by_selected_method
    _run_raw_task(args, ti)
  File "/home/airflow/.local/lib/python3.6/site-packages/airflow/cli/commands/task_command.py", line 184, in _run_raw_task
    error_file=args.error_file,
  File "/home/airflow/.local/lib/python3.6/site-packages/airflow/utils/session.py", line 70, in wrapper
    return func(*args, session=session, **kwargs)
  File "/home/airflow/.local/lib/python3.6/site-packages/airflow/models/taskinstance.py", line 1324, in _run_raw_task
    self._execute_task_with_callbacks(context)
  File "/home/airflow/.local/lib/python3.6/site-packages/airflow/models/taskinstance.py", line 1443, in _execute_task_with_callbacks
    result = self._execute_task(context, self.task)
  File "/home/airflow/.local/lib/python3.6/site-packages/airflow/models/taskinstance.py", line 1499, in _execute_task
    result = execute_callable(context=context)
  File "/home/airflow/.local/lib/python3.6/site-packages/airflow/operators/python.py", line 151, in execute
    return_value = self.execute_callable()
  File "/home/airflow/.local/lib/python3.6/site-packages/airflow/operators/python.py", line 162, in execute_callable
    return self.python_callable(*self.op_args, **self.op_kwargs)
  File "/opt/airflow/dags/ELT_VehiclePositions.py", line 16, in _load_gtfs
    load_gtfs(path)
  File "/opt/airflow/dags/gtfs_elt/functions.py", line 71, in load_gtfs
    with open(path, 'rb') as f:
FileNotFoundError: [Errno 2] No such file or directory: 'vehiclePositions/2022-01-30/vehiclePositions_1643596644'
[2022-01-31 02:37:27,945] {local_task_job.py:154} INFO - Task exited with return code 1
[2022-01-31 02:37:28,081] {local_task_job.py:264} INFO - 0 downstream tasks scheduled from follow-on schedule check
