[2022-01-31 03:46:59,270] {taskinstance.py:1035} INFO - Dependencies all met for <TaskInstance: extract_load_vehpo.load_vehiclePositions scheduled__2022-01-31T03:45:54.662875+00:00 [queued]>
[2022-01-31 03:46:59,280] {taskinstance.py:1035} INFO - Dependencies all met for <TaskInstance: extract_load_vehpo.load_vehiclePositions scheduled__2022-01-31T03:45:54.662875+00:00 [queued]>
[2022-01-31 03:46:59,281] {taskinstance.py:1241} INFO - 
--------------------------------------------------------------------------------
[2022-01-31 03:46:59,284] {taskinstance.py:1242} INFO - Starting attempt 1 of 1
[2022-01-31 03:46:59,285] {taskinstance.py:1243} INFO - 
--------------------------------------------------------------------------------
[2022-01-31 03:46:59,302] {taskinstance.py:1262} INFO - Executing <Task(PythonOperator): load_vehiclePositions> on 2022-01-31 03:45:54.662875+00:00
[2022-01-31 03:46:59,309] {standard_task_runner.py:52} INFO - Started process 5021 to run task
[2022-01-31 03:46:59,312] {standard_task_runner.py:76} INFO - Running: ['***', 'tasks', 'run', 'extract_load_vehpo', 'load_vehiclePositions', 'scheduled__2022-01-31T03:45:54.662875+00:00', '--job-id', '176', '--raw', '--subdir', 'DAGS_FOLDER/ELT_VehiclePositions.py', '--cfg-path', '/tmp/tmptemk3129', '--error-file', '/tmp/tmpel08dxha']
[2022-01-31 03:46:59,318] {standard_task_runner.py:77} INFO - Job 176: Subtask load_vehiclePositions
[2022-01-31 03:46:59,357] {logging_mixin.py:109} INFO - Running <TaskInstance: extract_load_vehpo.load_vehiclePositions scheduled__2022-01-31T03:45:54.662875+00:00 [running]> on host 932e3c301250
[2022-01-31 03:46:59,400] {taskinstance.py:1414} INFO - Exporting the following env vars:
AIRFLOW_CTX_DAG_OWNER=juan
AIRFLOW_CTX_DAG_ID=extract_load_vehpo
AIRFLOW_CTX_TASK_ID=load_vehiclePositions
AIRFLOW_CTX_EXECUTION_DATE=2022-01-31T03:45:54.662875+00:00
AIRFLOW_CTX_DAG_RUN_ID=scheduled__2022-01-31T03:45:54.662875+00:00
[2022-01-31 03:46:59,470] {taskinstance.py:1686} ERROR - Task failed with exception
Traceback (most recent call last):
  File "/home/airflow/.local/lib/python3.6/site-packages/sqlalchemy/engine/base.py", line 1277, in _execute_context
    cursor, statement, parameters, context
  File "/home/airflow/.local/lib/python3.6/site-packages/sqlalchemy/engine/default.py", line 608, in do_execute
    cursor.execute(statement, parameters)
psycopg2.errors.UndefinedTable: relation "vehicle_positions" does not exist
LINE 2: FROM vehicle_positions 
             ^


The above exception was the direct cause of the following exception:

Traceback (most recent call last):
  File "/home/airflow/.local/lib/python3.6/site-packages/airflow/models/taskinstance.py", line 1324, in _run_raw_task
    self._execute_task_with_callbacks(context)
  File "/home/airflow/.local/lib/python3.6/site-packages/airflow/models/taskinstance.py", line 1443, in _execute_task_with_callbacks
    result = self._execute_task(context, self.task)
  File "/home/airflow/.local/lib/python3.6/site-packages/airflow/models/taskinstance.py", line 1499, in _execute_task
    result = execute_callable(context=context)
  File "/home/airflow/.local/lib/python3.6/site-packages/airflow/operators/python.py", line 151, in execute
    return_value = self.execute_callable()
  File "/home/airflow/.local/lib/python3.6/site-packages/airflow/operators/python.py", line 162, in execute_callable
    return self.python_callable(*self.op_args, **self.op_kwargs)
  File "/opt/airflow/dags/ELT_VehiclePositions.py", line 16, in _load_gtfs
    load_gtfs(path)
  File "/opt/airflow/dags/gtfs_elt/functions.py", line 89, in load_gtfs
    check_duplicados = postgres_client._session.query(VehiclePositions).filter_by(id=id,feed_timestamp=feed_timestamp).first()
  File "/home/airflow/.local/lib/python3.6/site-packages/sqlalchemy/orm/query.py", line 3429, in first
    ret = list(self[0:1])
  File "/home/airflow/.local/lib/python3.6/site-packages/sqlalchemy/orm/query.py", line 3203, in __getitem__
    return list(res)
  File "/home/airflow/.local/lib/python3.6/site-packages/sqlalchemy/orm/query.py", line 3535, in __iter__
    return self._execute_and_instances(context)
  File "/home/airflow/.local/lib/python3.6/site-packages/sqlalchemy/orm/query.py", line 3560, in _execute_and_instances
    result = conn.execute(querycontext.statement, self._params)
  File "/home/airflow/.local/lib/python3.6/site-packages/sqlalchemy/engine/base.py", line 1011, in execute
    return meth(self, multiparams, params)
  File "/home/airflow/.local/lib/python3.6/site-packages/sqlalchemy/sql/elements.py", line 298, in _execute_on_connection
    return connection._execute_clauseelement(self, multiparams, params)
  File "/home/airflow/.local/lib/python3.6/site-packages/sqlalchemy/engine/base.py", line 1130, in _execute_clauseelement
    distilled_params,
  File "/home/airflow/.local/lib/python3.6/site-packages/sqlalchemy/engine/base.py", line 1317, in _execute_context
    e, statement, parameters, cursor, context
  File "/home/airflow/.local/lib/python3.6/site-packages/sqlalchemy/engine/base.py", line 1511, in _handle_dbapi_exception
    sqlalchemy_exception, with_traceback=exc_info[2], from_=e
  File "/home/airflow/.local/lib/python3.6/site-packages/sqlalchemy/util/compat.py", line 182, in raise_
    raise exception
  File "/home/airflow/.local/lib/python3.6/site-packages/sqlalchemy/engine/base.py", line 1277, in _execute_context
    cursor, statement, parameters, context
  File "/home/airflow/.local/lib/python3.6/site-packages/sqlalchemy/engine/default.py", line 608, in do_execute
    cursor.execute(statement, parameters)
sqlalchemy.exc.ProgrammingError: (psycopg2.errors.UndefinedTable) relation "vehicle_positions" does not exist
LINE 2: FROM vehicle_positions 
             ^

[SQL: SELECT vehicle_positions.id AS vehicle_positions_id, vehicle_positions.trip_id AS vehicle_positions_trip_id, vehicle_positions.vehicle_id AS vehicle_positions_vehicle_id, vehicle_positions.feed_timestamp AS vehicle_positions_feed_timestamp, vehicle_positions.vehicle_timestamp AS vehicle_positions_vehicle_timestamp, vehicle_positions.schedule_relationship AS vehicle_positions_schedule_relationship, vehicle_positions.latitude AS vehicle_positions_latitude, vehicle_positions.longitude AS vehicle_positions_longitude, vehicle_positions.bearing AS vehicle_positions_bearing, vehicle_positions.speed AS vehicle_positions_speed 
FROM vehicle_positions 
WHERE vehicle_positions.id = %(id_1)s AND vehicle_positions.feed_timestamp = %(feed_timestamp_1)s 
 LIMIT %(param_1)s]
[parameters: {'id_1': '1', 'feed_timestamp_1': 1643600816, 'param_1': 1}]
(Background on this error at: http://sqlalche.me/e/13/f405)
[2022-01-31 03:46:59,491] {taskinstance.py:1280} INFO - Marking task as FAILED. dag_id=extract_load_vehpo, task_id=load_vehiclePositions, execution_date=20220131T034554, start_date=20220131T034659, end_date=20220131T034659
[2022-01-31 03:46:59,504] {standard_task_runner.py:91} ERROR - Failed to execute job 176 for task load_vehiclePositions
Traceback (most recent call last):
  File "/home/airflow/.local/lib/python3.6/site-packages/sqlalchemy/engine/base.py", line 1277, in _execute_context
    cursor, statement, parameters, context
  File "/home/airflow/.local/lib/python3.6/site-packages/sqlalchemy/engine/default.py", line 608, in do_execute
    cursor.execute(statement, parameters)
psycopg2.errors.UndefinedTable: relation "vehicle_positions" does not exist
LINE 2: FROM vehicle_positions 
             ^


The above exception was the direct cause of the following exception:

Traceback (most recent call last):
  File "/home/airflow/.local/lib/python3.6/site-packages/airflow/task/task_runner/standard_task_runner.py", line 85, in _start_by_fork
    args.func(args, dag=self.dag)
  File "/home/airflow/.local/lib/python3.6/site-packages/airflow/cli/cli_parser.py", line 48, in command
    return func(*args, **kwargs)
  File "/home/airflow/.local/lib/python3.6/site-packages/airflow/utils/cli.py", line 92, in wrapper
    return f(*args, **kwargs)
  File "/home/airflow/.local/lib/python3.6/site-packages/airflow/cli/commands/task_command.py", line 292, in task_run
    _run_task_by_selected_method(args, dag, ti)
  File "/home/airflow/.local/lib/python3.6/site-packages/airflow/cli/commands/task_command.py", line 107, in _run_task_by_selected_method
    _run_raw_task(args, ti)
  File "/home/airflow/.local/lib/python3.6/site-packages/airflow/cli/commands/task_command.py", line 184, in _run_raw_task
    error_file=args.error_file,
  File "/home/airflow/.local/lib/python3.6/site-packages/airflow/utils/session.py", line 70, in wrapper
    return func(*args, session=session, **kwargs)
  File "/home/airflow/.local/lib/python3.6/site-packages/airflow/models/taskinstance.py", line 1324, in _run_raw_task
    self._execute_task_with_callbacks(context)
  File "/home/airflow/.local/lib/python3.6/site-packages/airflow/models/taskinstance.py", line 1443, in _execute_task_with_callbacks
    result = self._execute_task(context, self.task)
  File "/home/airflow/.local/lib/python3.6/site-packages/airflow/models/taskinstance.py", line 1499, in _execute_task
    result = execute_callable(context=context)
  File "/home/airflow/.local/lib/python3.6/site-packages/airflow/operators/python.py", line 151, in execute
    return_value = self.execute_callable()
  File "/home/airflow/.local/lib/python3.6/site-packages/airflow/operators/python.py", line 162, in execute_callable
    return self.python_callable(*self.op_args, **self.op_kwargs)
  File "/opt/airflow/dags/ELT_VehiclePositions.py", line 16, in _load_gtfs
    load_gtfs(path)
  File "/opt/airflow/dags/gtfs_elt/functions.py", line 89, in load_gtfs
    check_duplicados = postgres_client._session.query(VehiclePositions).filter_by(id=id,feed_timestamp=feed_timestamp).first()
  File "/home/airflow/.local/lib/python3.6/site-packages/sqlalchemy/orm/query.py", line 3429, in first
    ret = list(self[0:1])
  File "/home/airflow/.local/lib/python3.6/site-packages/sqlalchemy/orm/query.py", line 3203, in __getitem__
    return list(res)
  File "/home/airflow/.local/lib/python3.6/site-packages/sqlalchemy/orm/query.py", line 3535, in __iter__
    return self._execute_and_instances(context)
  File "/home/airflow/.local/lib/python3.6/site-packages/sqlalchemy/orm/query.py", line 3560, in _execute_and_instances
    result = conn.execute(querycontext.statement, self._params)
  File "/home/airflow/.local/lib/python3.6/site-packages/sqlalchemy/engine/base.py", line 1011, in execute
    return meth(self, multiparams, params)
  File "/home/airflow/.local/lib/python3.6/site-packages/sqlalchemy/sql/elements.py", line 298, in _execute_on_connection
    return connection._execute_clauseelement(self, multiparams, params)
  File "/home/airflow/.local/lib/python3.6/site-packages/sqlalchemy/engine/base.py", line 1130, in _execute_clauseelement
    distilled_params,
  File "/home/airflow/.local/lib/python3.6/site-packages/sqlalchemy/engine/base.py", line 1317, in _execute_context
    e, statement, parameters, cursor, context
  File "/home/airflow/.local/lib/python3.6/site-packages/sqlalchemy/engine/base.py", line 1511, in _handle_dbapi_exception
    sqlalchemy_exception, with_traceback=exc_info[2], from_=e
  File "/home/airflow/.local/lib/python3.6/site-packages/sqlalchemy/util/compat.py", line 182, in raise_
    raise exception
  File "/home/airflow/.local/lib/python3.6/site-packages/sqlalchemy/engine/base.py", line 1277, in _execute_context
    cursor, statement, parameters, context
  File "/home/airflow/.local/lib/python3.6/site-packages/sqlalchemy/engine/default.py", line 608, in do_execute
    cursor.execute(statement, parameters)
sqlalchemy.exc.ProgrammingError: (psycopg2.errors.UndefinedTable) relation "vehicle_positions" does not exist
LINE 2: FROM vehicle_positions 
             ^

[SQL: SELECT vehicle_positions.id AS vehicle_positions_id, vehicle_positions.trip_id AS vehicle_positions_trip_id, vehicle_positions.vehicle_id AS vehicle_positions_vehicle_id, vehicle_positions.feed_timestamp AS vehicle_positions_feed_timestamp, vehicle_positions.vehicle_timestamp AS vehicle_positions_vehicle_timestamp, vehicle_positions.schedule_relationship AS vehicle_positions_schedule_relationship, vehicle_positions.latitude AS vehicle_positions_latitude, vehicle_positions.longitude AS vehicle_positions_longitude, vehicle_positions.bearing AS vehicle_positions_bearing, vehicle_positions.speed AS vehicle_positions_speed 
FROM vehicle_positions 
WHERE vehicle_positions.id = %(id_1)s AND vehicle_positions.feed_timestamp = %(feed_timestamp_1)s 
 LIMIT %(param_1)s]
[parameters: {'id_1': '1', 'feed_timestamp_1': 1643600816, 'param_1': 1}]
(Background on this error at: http://sqlalche.me/e/13/f405)
[2022-01-31 03:46:59,526] {local_task_job.py:154} INFO - Task exited with return code 1
[2022-01-31 03:46:59,564] {local_task_job.py:264} INFO - 0 downstream tasks scheduled from follow-on schedule check
