[2022-01-31 02:37:28,808] {taskinstance.py:1035} INFO - Dependencies all met for <TaskInstance: extract_load_vehpo.load_vehiclePositions scheduled__2022-01-31T02:36:21.659161+00:00 [queued]>
[2022-01-31 02:37:28,836] {taskinstance.py:1035} INFO - Dependencies all met for <TaskInstance: extract_load_vehpo.load_vehiclePositions scheduled__2022-01-31T02:36:21.659161+00:00 [queued]>
[2022-01-31 02:37:28,838] {taskinstance.py:1241} INFO - 
--------------------------------------------------------------------------------
[2022-01-31 02:37:28,839] {taskinstance.py:1242} INFO - Starting attempt 1 of 1
[2022-01-31 02:37:28,840] {taskinstance.py:1243} INFO - 
--------------------------------------------------------------------------------
[2022-01-31 02:37:28,866] {taskinstance.py:1262} INFO - Executing <Task(PythonOperator): load_vehiclePositions> on 2022-01-31 02:36:21.659161+00:00
[2022-01-31 02:37:28,878] {standard_task_runner.py:52} INFO - Started process 1280 to run task
[2022-01-31 02:37:28,883] {standard_task_runner.py:76} INFO - Running: ['***', 'tasks', 'run', 'extract_load_vehpo', 'load_vehiclePositions', 'scheduled__2022-01-31T02:36:21.659161+00:00', '--job-id', '34', '--raw', '--subdir', 'DAGS_FOLDER/ELT_VehiclePositions.py', '--cfg-path', '/tmp/tmpdqiljl9z', '--error-file', '/tmp/tmptmxnq6oj']
[2022-01-31 02:37:28,904] {standard_task_runner.py:77} INFO - Job 34: Subtask load_vehiclePositions
[2022-01-31 02:37:28,981] {logging_mixin.py:109} INFO - Running <TaskInstance: extract_load_vehpo.load_vehiclePositions scheduled__2022-01-31T02:36:21.659161+00:00 [running]> on host 932e3c301250
[2022-01-31 02:37:29,047] {taskinstance.py:1414} INFO - Exporting the following env vars:
AIRFLOW_CTX_DAG_OWNER=juan
AIRFLOW_CTX_DAG_ID=extract_load_vehpo
AIRFLOW_CTX_TASK_ID=load_vehiclePositions
AIRFLOW_CTX_EXECUTION_DATE=2022-01-31T02:36:21.659161+00:00
AIRFLOW_CTX_DAG_RUN_ID=scheduled__2022-01-31T02:36:21.659161+00:00
[2022-01-31 02:37:29,061] {taskinstance.py:1686} ERROR - Task failed with exception
Traceback (most recent call last):
  File "/home/airflow/.local/lib/python3.6/site-packages/airflow/models/taskinstance.py", line 1324, in _run_raw_task
    self._execute_task_with_callbacks(context)
  File "/home/airflow/.local/lib/python3.6/site-packages/airflow/models/taskinstance.py", line 1443, in _execute_task_with_callbacks
    result = self._execute_task(context, self.task)
  File "/home/airflow/.local/lib/python3.6/site-packages/airflow/models/taskinstance.py", line 1499, in _execute_task
    result = execute_callable(context=context)
  File "/home/airflow/.local/lib/python3.6/site-packages/airflow/operators/python.py", line 151, in execute
    return_value = self.execute_callable()
  File "/home/airflow/.local/lib/python3.6/site-packages/airflow/operators/python.py", line 162, in execute_callable
    return self.python_callable(*self.op_args, **self.op_kwargs)
  File "/opt/airflow/dags/ELT_VehiclePositions.py", line 16, in _load_gtfs
    load_gtfs(path)
  File "/opt/airflow/dags/gtfs_elt/functions.py", line 71, in load_gtfs
    with open(path, 'rb') as f:
FileNotFoundError: [Errno 2] No such file or directory: 'vehiclePositions/2022-01-30/vehiclePositions_1643596646'
[2022-01-31 02:37:29,080] {taskinstance.py:1280} INFO - Marking task as FAILED. dag_id=extract_load_vehpo, task_id=load_vehiclePositions, execution_date=20220131T023621, start_date=20220131T023728, end_date=20220131T023729
[2022-01-31 02:37:29,105] {standard_task_runner.py:91} ERROR - Failed to execute job 34 for task load_vehiclePositions
Traceback (most recent call last):
  File "/home/airflow/.local/lib/python3.6/site-packages/airflow/task/task_runner/standard_task_runner.py", line 85, in _start_by_fork
    args.func(args, dag=self.dag)
  File "/home/airflow/.local/lib/python3.6/site-packages/airflow/cli/cli_parser.py", line 48, in command
    return func(*args, **kwargs)
  File "/home/airflow/.local/lib/python3.6/site-packages/airflow/utils/cli.py", line 92, in wrapper
    return f(*args, **kwargs)
  File "/home/airflow/.local/lib/python3.6/site-packages/airflow/cli/commands/task_command.py", line 292, in task_run
    _run_task_by_selected_method(args, dag, ti)
  File "/home/airflow/.local/lib/python3.6/site-packages/airflow/cli/commands/task_command.py", line 107, in _run_task_by_selected_method
    _run_raw_task(args, ti)
  File "/home/airflow/.local/lib/python3.6/site-packages/airflow/cli/commands/task_command.py", line 184, in _run_raw_task
    error_file=args.error_file,
  File "/home/airflow/.local/lib/python3.6/site-packages/airflow/utils/session.py", line 70, in wrapper
    return func(*args, session=session, **kwargs)
  File "/home/airflow/.local/lib/python3.6/site-packages/airflow/models/taskinstance.py", line 1324, in _run_raw_task
    self._execute_task_with_callbacks(context)
  File "/home/airflow/.local/lib/python3.6/site-packages/airflow/models/taskinstance.py", line 1443, in _execute_task_with_callbacks
    result = self._execute_task(context, self.task)
  File "/home/airflow/.local/lib/python3.6/site-packages/airflow/models/taskinstance.py", line 1499, in _execute_task
    result = execute_callable(context=context)
  File "/home/airflow/.local/lib/python3.6/site-packages/airflow/operators/python.py", line 151, in execute
    return_value = self.execute_callable()
  File "/home/airflow/.local/lib/python3.6/site-packages/airflow/operators/python.py", line 162, in execute_callable
    return self.python_callable(*self.op_args, **self.op_kwargs)
  File "/opt/airflow/dags/ELT_VehiclePositions.py", line 16, in _load_gtfs
    load_gtfs(path)
  File "/opt/airflow/dags/gtfs_elt/functions.py", line 71, in load_gtfs
    with open(path, 'rb') as f:
FileNotFoundError: [Errno 2] No such file or directory: 'vehiclePositions/2022-01-30/vehiclePositions_1643596646'
[2022-01-31 02:37:29,144] {local_task_job.py:154} INFO - Task exited with return code 1
[2022-01-31 02:37:29,188] {local_task_job.py:264} INFO - 0 downstream tasks scheduled from follow-on schedule check
